<?xml version="1.0" encoding="utf-8"?>
<!-- This URDF was automatically created by SolidWorks to URDF Exporter! Originally created by Stephen Brawner (brawner@gmail.com) 
     Commit Version: 1.6.0-4-g7f85cfe  Build Version: 1.6.7995.38578
     For more information, please see http://wiki.ros.org/sw_urdf_exporter -->
<robot
  name="rh1621hand_y">
  <link
    name="base_link">
    <inertial>
      <origin
        xyz="0.00120473170813106 0.00137328132727926 0.0629045033301865"
        rpy="0 0 0" />
      <mass
        value="0.323794541220413" />
      <inertia
        ixx="0.000306129659024941"
        ixy="-9.39857008572514E-07"
        ixz="7.62059830173208E-06"
        iyy="0.000150290127101325"
        iyz="-6.32299865006161E-06"
        izz="0.000205207376543336" />
    </inertial>
    <visual>
      <origin
        xyz="0 0 0"
        rpy="0 0 0" />
      <geometry>
        <mesh
          filename="package://rh1621hand_y/meshes/base_link.STL" />
      </geometry>
      <material
	      name="">
        <color rgba="0.898039215686275 0.917647058823529 0.929411764705882 1" />
      </material>
    </visual>
    <collision>
      <origin
        xyz="0 0 0"
        rpy="0 0 0" />
      <geometry>
        <mesh
          filename="package://rh1621hand_y/meshes/base_link.STL" />
      </geometry>
    </collision>
  </link>
  <link
    name="fy1611_Link">
    <inertial>
      <origin
        xyz="0.012596597271034 -0.00780664433208217 0.00876262487453297"
        rpy="0 0 0" />
      <mass
        value="0.0194286583912513" />
      <inertia
        ixx="1.79645530053988E-06"
        ixy="8.62590850166143E-07"
        ixz="-4.17065258430338E-08"
        iyy="3.58449792069552E-06"
        iyz="-7.30260475392558E-08"
        izz="3.94016920687781E-06" />
    </inertial>
    <visual>
      <origin
        xyz="0 0 0"
        rpy="0 0 0" />
      <geometry>
        <mesh
          filename="package://rh1621hand_y/meshes/fy1611_Link.STL" />
      </geometry>
      <material
	      name="">
        <color
          rgba="0.898039215686275 0.917647058823529 0.929411764705882 1" />
      </material>
    </visual>
    <collision>
      <origin
        xyz="0 0 0"
        rpy="0 0 0" />
      <geometry>
        <mesh
          filename="package://rh1621hand_y/meshes/fy1611_Link.STL" />
      </geometry>
    </collision>
  </link>
  <joint
    name="fy1611"
    type="revolute">
    <origin
      xyz="0.025 0.016 0.0368"
      rpy="0 0 1.5708" />
    <parent
      link="base_link" />
    <child
      link="fy1611_Link" />
    <axis
      xyz="0 0 -1" />
    <limit
      lower="0"
      upper="1.9199"
      effort="0"
      velocity="0" />
  </joint>
  <link
    name="fy1612_Link">
    <inertial>
      <origin
        xyz="-0.000899580500523495 -0.00636666624809215 0.00699999996511357"
        rpy="0 0 0" />
      <mass
        value="0.00158680675695732" />
      <inertia
        ixx="6.70354992304236E-08"
        ixy="-4.98048981588713E-09"
        ixz="-3.2852976899493E-16"
        iyy="3.24904292793987E-08"
        iyz="-2.25040503930264E-16"
        izz="4.46519285358428E-08" />
    </inertial>
    <visual>
      <origin
        xyz="0 0 0"
        rpy="0 0 0" />
      <geometry>
        <mesh
          filename="package://rh1621hand_y/meshes/fy1612_Link.STL" />
      </geometry>
      <material
	      name="">
        <color
          rgba="0.898039215686275 0.917647058823529 0.929411764705882 1" />
      </material>
    </visual>
    <collision>
      <origin
        xyz="0 0 0"
        rpy="0 0 0" />
      <geometry>
        <mesh
          filename="package://rh1621hand_y/meshes/fy1612_Link.STL" />
      </geometry>
    </collision>
  </link>
  <joint
    name="fy1612"
    type="revolute">
    <origin
      xyz="0.02789 -0.019802 0.0222"
      rpy="-1.5708 0 0.043633" />
    <parent
      link="fy1611_Link" />
    <child
      link="fy1612_Link" />
    <axis
      xyz="0 0 -1" />
    <limit
      lower="0"
      upper="1.25"
      effort="0"
      velocity="0" />
  </joint>
  <link
    name="fy1613_Link">
    <inertial>
      <origin
        xyz="0.0241638999764132 -0.0010436834408553 0.00761216871257973"
        rpy="0 0 0" />
      <mass
        value="0.033516665822624" />
      <inertia
        ixx="2.45019102843852E-06"
        ixy="3.99288424245579E-08"
        ixz="-2.77043869647154E-07"
        iyy="3.23735960617771E-06"
        iyz="-3.02480214575702E-08"
        izz="2.39128179652899E-06" />
    </inertial>
    <visual>
      <origin
        xyz="0 0 0"
        rpy="0 0 0" />
      <geometry>
        <mesh
          filename="package://rh1621hand_y/meshes/fy1613_Link.STL" />
      </geometry>
      <material
	      name="">
        <color
          rgba="0.898039215686275 0.917647058823529 0.929411764705882 1" />
      </material>
    </visual>
    <collision>
      <origin
        xyz="0 0 0"
        rpy="0 0 0" />
      <geometry>
        <mesh
          filename="package://rh1621hand_y/meshes/fy1613_Link.STL" />
      </geometry>
    </collision>
  </link>
  <joint
    name="fy1613"
    type="revolute">
    <origin
      xyz="-0.0024344 -0.017229 0.007"
      rpy="-1.5708 0.044066 -0.14037" />
    <parent
      link="fy1612_Link" />
    <child
      link="fy1613_Link" />
    <axis
      xyz="0 0 -1" />
    <limit
      lower="-0.349"
      upper="0.349"
      effort="0"
      velocity="0" />
  </joint>
  <link
    name="fy1614_Link">
    <inertial>
      <origin
        xyz="0.0121937640220311 -0.00268695608056291 0.00877160210046214"
        rpy="0 0 0" />
      <mass
        value="0.0045424671173164" />
      <inertia
        ixx="1.60187703389592E-07"
        ixy="6.29951566843612E-08"
        ixz="-1.51510028302852E-08"
        iyy="3.61297909890129E-07"
        iyz="3.68566582637844E-09"
        izz="4.58781746526855E-07" />
    </inertial>
    <visual>
      <origin
        xyz="0 0 0"
        rpy="0 0 0" />
      <geometry>
        <mesh
          filename="package://rh1621hand_y/meshes/fy1614_Link.STL" />
      </geometry>
      <material
	      name="">
        <color
          rgba="0.898039215686275 0.917647058823529 0.929411764705882 1" />
      </material>
    </visual>
    <collision>
      <origin
        xyz="0 0 0"
        rpy="0 0 0" />
      <geometry>
        <mesh
          filename="package://rh1621hand_y/meshes/fy1614_Link.STL" />
      </geometry>
    </collision>
  </link>
  <joint
    name="fy1614"
    type="revolute">
    <origin
      xyz="0.063356 0.0054804 0.0101"
      rpy="1.5646 -0.14023 0" />
    <parent
      link="fy1613_Link" />
    <child
      link="fy1614_Link" />
    <axis
      xyz="0 0 -1" />
    <limit
      lower="0"
      upper="1.335"
      effort="0"
      velocity="0" />
  </joint>
  <link
    name="fy1615_Link">
    <inertial>
      <origin
        xyz="0.00344100542841774 0.00378637298458219 0.00782339193650556"
        rpy="0 0 0" />
      <mass
        value="0.00405495169403808" />
      <inertia
        ixx="1.72241333622285E-07"
        ixy="-7.79000200903929E-08"
        ixz="-7.20142066389312E-09"
        iyy="3.19029234010063E-07"
        iyz="-3.40650990649968E-09"
        izz="3.36786208504926E-07" />
    </inertial>
    <visual>
      <origin
        xyz="0 0 0"
        rpy="0 0 0" />
      <geometry>
        <mesh
          filename="package://rh1621hand_y/meshes/fy1615_Link.STL" />
      </geometry>
      <material
	      name="">
        <color
          rgba="0.898039215686275 0.917647058823529 0.929411764705882 1" />
      </material>
    </visual>
    <collision>
      <origin
        xyz="0 0 0"
        rpy="0 0 0" />
      <geometry>
        <mesh
          filename="package://rh1621hand_y/meshes/fy1615_Link.STL" />
      </geometry>
    </collision>
  </link>
  <joint
    name="fy1615"
    type="revolute">
    <origin
      xyz="0.026258 -0.0073189 0.001747"
      rpy="0 0 0" />
    <parent
      link="fy1614_Link" />
    <child
      link="fy1615_Link" />
    <axis
      xyz="0 0 -1" />
    <limit
      lower="0"
      upper="1.163"
      effort="0"
      velocity="0" />
    <mimic joint="fy1614" multiplier="1.0" offset="0.0"/>
  </joint>
  <link
    name="fy1616_Link">
    <inertial>
      <origin
        xyz="-0.000245086398472871 0.000640124509888935 -0.00558811484217853"
        rpy="0 0 0" />
      <mass
        value="0.00215225080577561" />
      <inertia
        ixx="1.24831750937643E-07"
        ixy="7.70312508041518E-10"
        ixz="-1.29456482972833E-09"
        iyy="1.64074682503423E-07"
        iyz="1.68382567860798E-08"
        izz="9.63427955099581E-08" />
    </inertial>
    <visual>
      <origin
        xyz="0 0 0"
        rpy="0 0 0" />
      <geometry>
        <mesh
          filename="package://rh1621hand_y/meshes/fy1616_Link.STL" />
      </geometry>
      <material
	      name="">
        <color
          rgba="0.298039215686275 0.298039215686275 0.298039215686275 1" />
      </material>
    </visual>
    <collision>
      <origin
        xyz="0 0 0"
        rpy="0 0 0" />
      <geometry>
        <mesh
          filename="package://rh1621hand_y/meshes/fy1616_Link.STL" />
      </geometry>
    </collision>
  </link>
  <joint
    name="fy1616"
    type="revolute">
    <origin
      xyz="0.018488 0.0013515 0.0084805"
      rpy="-3.1416 -1.5708 0" />
    <parent
      link="fy1615_Link" />
    <child
      link="fy1616_Link" />
    <axis
      xyz="0 0 -1" />
    <limit
      lower="0"
      upper="0"
      effort="0"
      velocity="0" />
  </joint>
  <link
    name="fy1621_Link">
    <inertial>
      <origin
        xyz="0 0 0.0144895176625968"
        rpy="0 0 0" />
      <mass
        value="0.00163674187446043" />
      <inertia
        ixx="4.95179442076947E-08"
        ixy="-3.55735142967733E-11"
        ixz="1.35095260020427E-21"
        iyy="8.54469633350302E-08"
        iyz="-1.33290156561248E-18"
        izz="4.31474049831043E-08" />
    </inertial>
    <visual>
      <origin
        xyz="0 0 0"
        rpy="0 0 0" />
      <geometry>
        <mesh
          filename="package://rh1621hand_y/meshes/fy1621_Link.STL" />
      </geometry>
      <material
	      name="">
        <color
          rgba="0.898039215686275 0.917647058823529 0.929411764705882 1" />
      </material>
    </visual>
    <collision>
      <origin
        xyz="0 0 0"
        rpy="0 0 0" />
      <geometry>
        <mesh
          filename="package://rh1621hand_y/meshes/fy1621_Link.STL" />
      </geometry>
    </collision>
  </link>
  <joint
    name="fy1621"
    type="revolute">
    <origin
      xyz="-0.018 0.03525 0.1175"
      rpy="1.5708 0 1.5708" />
    <parent
      link="base_link" />
    <child
      link="fy1621_Link" />
    <axis
      xyz="0 0 1" />
    <limit
      lower="-0.349"
      upper="0.349"
      effort="0"
      velocity="0" />
  </joint>
  <link
    name="fy1622_Link">
    <inertial>
      <origin
        xyz="-0.0216856217739387 0.000531167122641337 0.010622198265055"
        rpy="0 0 0" />
      <mass
        value="0.00954315742392436" />
      <inertia
        ixx="3.91451099504246E-07"
        ixy="2.95838338679619E-08"
        ixz="2.0186960052317E-09"
        iyy="1.35747460657196E-06"
        iyz="1.48101901734629E-11"
        izz="1.63482724668025E-06" />
    </inertial>
    <visual>
      <origin
        xyz="0 0 0"
        rpy="0 0 0" />
      <geometry>
        <mesh
          filename="package://rh1621hand_y/meshes/fy1622_Link.STL" />
      </geometry>
      <material
	      name="">
        <color
          rgba="0.898039215686275 0.917647058823529 0.929411764705882 1" />
      </material>
    </visual>
    <collision>
      <origin
        xyz="0 0 0"
        rpy="0 0 0" />
      <geometry>
        <mesh
          filename="package://rh1621hand_y/meshes/fy1622_Link.STL" />
      </geometry>
    </collision>
  </link>
  <joint
    name="fy1622"
    type="revolute">
    <origin
      xyz="0.0105 1.0396E-05 0.0208"
      rpy="1.5708 0 -1.5698" />
    <parent
      link="fy1621_Link" />
    <child
      link="fy1622_Link" />
    <axis
      xyz="0 0 -1" />
    <limit
      lower="0"
      upper="1.557"
      effort="0"
      velocity="0" />
  </joint>
  <link
    name="fy1623_Link">
    <inertial>
      <origin
        xyz="-0.0127963350765614 0.00116053737575848 0.008265308549014"
        rpy="0 0 0" />
      <mass
        value="0.00454257479946939" />
      <inertia
        ixx="1.47314916539318E-07"
        ixy="3.7242079629733E-08"
        ixz="2.17740159924854E-09"
        iyy="3.73420473748306E-07"
        iyz="-6.78013232180622E-10"
        izz="4.59536116311346E-07" />
    </inertial>
    <visual>
      <origin
        xyz="0 0 0"
        rpy="0 0 0" />
      <geometry>
        <mesh
          filename="package://rh1621hand_y/meshes/fy1623_Link.STL" />
      </geometry>
      <material
	      name="">
        <color
          rgba="0.898039215686275 0.917647058823529 0.929411764705882 1" />
      </material>
    </visual>
    <collision>
      <origin
        xyz="0 0 0"
        rpy="0 0 0" />
      <geometry>
        <mesh
          filename="package://rh1621hand_y/meshes/fy1623_Link.STL" />
      </geometry>
    </collision>
  </link>
  <joint
    name="fy1623"
    type="revolute">
    <origin
      xyz="-0.03998 -0.0032593 0.0023"
      rpy="0 0 0" />
    <parent
      link="fy1622_Link" />
    <child
      link="fy1623_Link" />
    <axis
      xyz="0 0 -1" />
    <limit
      lower="0"
      upper="1.406"
      effort="0"
      velocity="0" />
  </joint>
  <link
    name="fy1624_Link">
    <inertial>
      <origin
        xyz="-0.00367976638052067 -0.00489152974241332 0.00829984230323905"
        rpy="0 0 0" />
      <mass
        value="0.00405498029461831" />
      <inertia
        ixx="1.94079484179635E-07"
        ixy="-9.40631813866874E-08"
        ixz="3.21463276177608E-12"
        iyy="2.96879098682251E-07"
        iyz="5.62356555736337E-12"
        izz="3.37103397672897E-07" />
    </inertial>
    <visual>
      <origin
        xyz="0 0 0"
        rpy="0 0 0" />
      <geometry>
        <mesh
          filename="package://rh1621hand_y/meshes/fy1624_Link.STL" />
      </geometry>
      <material
	      name="">
        <color
          rgba="0.898039215686275 0.917647058823529 0.929411764705882 1" />
      </material>
    </visual>
    <collision>
      <origin
        xyz="0 0 0"
        rpy="0 0 0" />
      <geometry>
        <mesh
          filename="package://rh1621hand_y/meshes/fy1624_Link.STL" />
      </geometry>
    </collision>
  </link>
  <joint
    name="fy1624"
    type="revolute">
    <origin
      xyz="-0.026577 0.0047606 0"
      rpy="0 0 0" />
    <parent
      link="fy1623_Link" />
    <child
      link="fy1624_Link" />
    <axis
      xyz="0 0 -1" />
    <limit
      lower="0"
      upper="1.169"
      effort="0"
      velocity="0" />
    <mimic joint="fy1623" multiplier="1.0" offset="0.0"/>
  </joint>
  <link
    name="fy1625_Link">
    <inertial>
      <origin
        xyz="6.88661679387748E-06 -0.00135005909762468 -0.00546629411921096"
        rpy="0 0 0" />
      <mass
        value="0.00215218770253425" />
      <inertia
        ixx="1.24856399689416E-07"
        ixy="6.62212180485777E-11"
        ixz="7.45541048187666E-11"
        iyy="1.58678535361779E-07"
        iyz="-2.48685172093236E-08"
        izz="1.01653754672077E-07" />
    </inertial>
    <visual>
      <origin
        xyz="0 0 0"
        rpy="0 0 0" />
      <geometry>
        <mesh
          filename="package://rh1621hand_y/meshes/fy1625_Link.STL" />
      </geometry>
      <material
	      name="">
        <color
          rgba="0.298039215686275 0.298039215686275 0.298039215686275 1" />
      </material>
    </visual>
    <collision>
      <origin
        xyz="0 0 0"
        rpy="0 0 0" />
      <geometry>
        <mesh
          filename="package://rh1621hand_y/meshes/fy1625_Link.STL" />
      </geometry>
    </collision>
  </link>
  <joint
    name="fy1625"
    type="revolute">
    <origin
      xyz="-0.018928 -0.0044 0.0083"
      rpy="-3.1416 1.5698 0" />
    <parent
      link="fy1624_Link" />
    <child
      link="fy1625_Link" />
    <axis
      xyz="0 0 -1" />
    <limit
      lower="0"
      upper="0"
      effort="0"
      velocity="0" />
  </joint>
  <link
    name="fy1631_Link">
    <inertial>
      <origin
        xyz="0 -1.38777878078145E-17 0.0144895176625968"
        rpy="0 0 0" />
      <mass
        value="0.00163674187446044" />
      <inertia
        ixx="4.9517944207695E-08"
        ixy="-3.55735142950989E-11"
        ixz="1.29054013648174E-21"
        iyy="8.54469633350311E-08"
        iyz="-1.33289897395758E-18"
        izz="4.3147404983105E-08" />
    </inertial>
    <visual>
      <origin
        xyz="0 0 0"
        rpy="0 0 0" />
      <geometry>
        <mesh
          filename="package://rh1621hand_y/meshes/fy1631_Link.STL" />
      </geometry>
      <material
	      name="">
        <color
          rgba="0.898039215686275 0.917647058823529 0.929411764705882 1" />
      </material>
    </visual>
    <collision>
      <origin
        xyz="0 0 0"
        rpy="0 0 0" />
      <geometry>
        <mesh
          filename="package://rh1621hand_y/meshes/fy1631_Link.STL" />
      </geometry>
    </collision>
  </link>
  <joint
    name="fy1631"
    type="revolute">
    <origin
      xyz="-0.018 0.01175 0.119"
      rpy="1.5708 0 1.5708" />
    <parent
      link="base_link" />
    <child
      link="fy1631_Link" />
    <axis
      xyz="0 0 1" />
    <limit
      lower="-0.349"
      upper="0.349"
      effort="0"
      velocity="0" />
  </joint>
  <link
    name="fy1632_Link">
    <inertial>
      <origin
        xyz="-0.0239106274078487 0.000576561773819196 0.0106170046662177"
        rpy="0 0 0" />
      <mass
        value="0.0106604335846991" />
      <inertia
        ixx="4.4782709640219E-07"
        ixy="3.48556224258222E-08"
        ixz="2.27390209153419E-09"
        iyy="1.91424265957534E-06"
        iyz="-1.37933886196141E-11"
        izz="2.2368033710404E-06" />
    </inertial>
    <visual>
      <origin
        xyz="0 0 0"
        rpy="0 0 0" />
      <geometry>
        <mesh
          filename="package://rh1621hand_y/meshes/fy1632_Link.STL" />
      </geometry>
      <material
	      name="">
        <color
          rgba="0.898039215686275 0.917647058823529 0.929411764705882 1" />
      </material>
    </visual>
    <collision>
      <origin
        xyz="0 0 0"
        rpy="0 0 0" />
      <geometry>
        <mesh
          filename="package://rh1621hand_y/meshes/fy1632_Link.STL" />
      </geometry>
    </collision>
  </link>
  <joint
    name="fy1632"
    type="revolute">
    <origin
      xyz="0.0105 1.0396E-05 0.0208"
      rpy="1.5708 0 -1.5698" />
    <parent
      link="fy1631_Link" />
    <child
      link="fy1632_Link" />
    <axis
      xyz="0 0 -1" />
    <limit
      lower="0"
      upper="1.557"
      effort="0"
      velocity="0" />
  </joint>
  <link
    name="fy1633_Link">
    <inertial>
      <origin
        xyz="-0.0128161419361256 0.000916382255055749 0.00826531161881497"
        rpy="0 0 0" />
      <mass
        value="0.00454255102577153" />
      <inertia
        ixx="1.45976674407602E-07"
        ixy="3.29049858000761E-08"
        ixz="2.18986582077932E-09"
        iyy="3.74757489354637E-07"
        iyz="-6.36133561983638E-10"
        izz="4.59535479452731E-07" />
    </inertial>
    <visual>
      <origin
        xyz="0 0 0"
        rpy="0 0 0" />
      <geometry>
        <mesh
          filename="package://rh1621hand_y/meshes/fy1633_Link.STL" />
      </geometry>
      <material
	      name="">
        <color
          rgba="0.898039215686275 0.917647058823529 0.929411764705882 1" />
      </material>
    </visual>
    <collision>
      <origin
        xyz="0 0 0"
        rpy="0 0 0" />
      <geometry>
        <mesh
          filename="package://rh1621hand_y/meshes/fy1633_Link.STL" />
      </geometry>
    </collision>
  </link>
  <joint
    name="fy1633"
    type="revolute">
    <origin
      xyz="-0.04498 -0.0032918 0.0023"
      rpy="0 0 0" />
    <parent
      link="fy1632_Link" />
    <child
      link="fy1633_Link" />
    <axis
      xyz="0 0 -1" />
    <limit
      lower="0"
      upper="1.391"
      effort="0"
      velocity="0" />
  </joint>
  <link
    name="fy1634_Link">
    <inertial>
      <origin
        xyz="-0.00349649570912366 -0.00502418460696475 0.00849984162741849"
        rpy="0 0 0" />
      <mass
        value="0.00405498371035952" />
      <inertia
        ixx="2.01167854281917E-07"
        ixy="-9.76030962569801E-08"
        ixz="3.1562721628921E-12"
        iyy="2.8979190409115E-07"
        iyz="5.85417239935553E-12"
        izz="3.3710487533344E-07" />
    </inertial>
    <visual>
      <origin
        xyz="0 0 0"
        rpy="0 0 0" />
      <geometry>
        <mesh
          filename="package://rh1621hand_y/meshes/fy1634_Link.STL" />
      </geometry>
      <material
	      name="">
        <color
          rgba="0.898039215686275 0.917647058823529 0.929411764705882 1" />
      </material>
    </visual>
    <collision>
      <origin
        xyz="0 0 0"
        rpy="0 0 0" />
      <geometry>
        <mesh
          filename="package://rh1621hand_y/meshes/fy1634_Link.STL" />
      </geometry>
    </collision>
  </link>
  <joint
    name="fy1634"
    type="revolute">
    <origin
      xyz="-0.026663 0.0042531 -0.0002"
      rpy="0 0 0" />
    <parent
      link="fy1633_Link" />
    <child
      link="fy1634_Link" />
    <axis
      xyz="0 0 -1" />
    <limit
      lower="0"
      upper="1.18"
      effort="0"
      velocity="0" />
    <mimic joint="fy1633" multiplier="1.0" offset="0.0"/>
  </joint>
  <link
    name="fy1635_Link">
    <inertial>
      <origin
        xyz="6.83657888583822E-06 -0.00155114760896818 -0.00541263111207904"
        rpy="0 0 0" />
      <mass
        value="0.00215219896994474" />
      <inertia
        ixx="1.24856664298405E-07"
        ixy="7.00756344049973E-11"
        ixz="7.0890816316758E-11"
        iyy="1.56764473094774E-07"
        iyz="-2.69063994389113E-08"
        izz="1.03568653126643E-07" />
    </inertial>
    <visual>
      <origin
        xyz="0 0 0"
        rpy="0 0 0" />
      <geometry>
        <mesh
          filename="package://rh1621hand_y/meshes/fy1635_Link.STL" />
      </geometry>
      <material
	      name="">
        <color
          rgba="0.298039215686275 0.298039215686275 0.298039215686275 1" />
      </material>
    </visual>
    <collision>
      <origin
        xyz="0 0 0"
        rpy="0 0 0" />
      <geometry>
        <mesh
          filename="package://rh1621hand_y/meshes/fy1635_Link.STL" />
      </geometry>
    </collision>
  </link>
  <joint
    name="fy1635"
    type="revolute">
    <origin
      xyz="-0.018753 -0.0050965 0.0085"
      rpy="-3.1416 1.5698 0" />
    <parent
      link="fy1634_Link" />
    <child
      link="fy1635_Link" />
    <axis
      xyz="0 0 -1" />
    <limit
      lower="0"
      upper="0"
      effort="0"
      velocity="0" />
  </joint>
  <link
    name="fy1641_Link">
    <inertial>
      <origin
        xyz="-1.38777878078145E-17 0 0.0144895176625967"
        rpy="0 0 0" />
      <mass
        value="0.00163674187446043" />
      <inertia
        ixx="4.95179442076946E-08"
        ixy="-3.55735142967618E-11"
        ixz="1.38478929165342E-21"
        iyy="8.54469633350299E-08"
        iyz="-1.33290727376776E-18"
        izz="4.31474049831042E-08" />
    </inertial>
    <visual>
      <origin
        xyz="0 0 0"
        rpy="0 0 0" />
      <geometry>
        <mesh
          filename="package://rh1621hand_y/meshes/fy1641_Link.STL" />
      </geometry>
      <material
	      name="">
        <color
          rgba="0.898039215686275 0.917647058823529 0.929411764705882 1" />
      </material>
    </visual>
    <collision>
      <origin
        xyz="0 0 0"
        rpy="0 0 0" />
      <geometry>
        <mesh
          filename="package://rh1621hand_y/meshes/fy1641_Link.STL" />
      </geometry>
    </collision>
  </link>
  <joint
    name="fy1641"
    type="revolute">
    <origin
      xyz="-0.018 -0.01175 0.1175"
      rpy="1.5708 0 1.5708" />
    <parent
      link="base_link" />
    <child
      link="fy1641_Link" />
    <axis
      xyz="0 0 1" />
    <limit
      lower="-0.349"
      upper="0.349"
      effort="0"
      velocity="0" />
  </joint>
  <link
    name="fy1642_Link">
    <inertial>
      <origin
        xyz="-0.0216856237266206 0.000531168985477505 0.0106222004453642"
        rpy="0 0 0" />
      <mass
        value="0.00954315744541886" />
      <inertia
        ixx="3.91451102071864E-07"
        ixy="2.95838321336046E-08"
        ixz="2.01869542793963E-09"
        iyy="1.3574746087359E-06"
        iyz="1.48096224555769E-11"
        izz="1.63482725106105E-06" />
    </inertial>
    <visual>
      <origin
        xyz="0 0 0"
        rpy="0 0 0" />
      <geometry>
        <mesh
          filename="package://rh1621hand_y/meshes/fy1642_Link.STL" />
      </geometry>
      <material
	      name="">
        <color
          rgba="0.898039215686275 0.917647058823529 0.929411764705882 1" />
      </material>
    </visual>
    <collision>
      <origin
        xyz="0 0 0"
        rpy="0 0 0" />
      <geometry>
        <mesh
          filename="package://rh1621hand_y/meshes/fy1642_Link.STL" />
      </geometry>
    </collision>
  </link>
  <joint
    name="fy1642"
    type="revolute">
    <origin
      xyz="0.0105 1.0396E-05 0.0208"
      rpy="1.5708 0 -1.5698" />
    <parent
      link="fy1641_Link" />
    <child
      link="fy1642_Link" />
    <axis
      xyz="0 0 -1" />
    <limit
      lower="0"
      upper="1.557"
      effort="0"
      velocity="0" />
  </joint>
  <link
    name="fy1643_Link">
    <inertial>
      <origin
        xyz="-0.0127963355053058 0.0011605381061548 0.00823130897344296"
        rpy="0 0 0" />
      <mass
        value="0.00454257517863332" />
      <inertia
        ixx="1.47314933096423E-07"
        ixy="3.72421025743861E-08"
        ixz="2.17739482730324E-09"
        iyy="3.73420483899908E-07"
        iyz="-6.78010306834203E-10"
        izz="4.59536150488761E-07" />
    </inertial>
    <visual>
      <origin
        xyz="0 0 0"
        rpy="0 0 0" />
      <geometry>
        <mesh
          filename="package://rh1621hand_y/meshes/fy1643_Link.STL" />
      </geometry>
      <material
	      name="">
        <color
          rgba="0.898039215686275 0.917647058823529 0.929411764705882 1" />
      </material>
    </visual>
    <collision>
      <origin
        xyz="0 0 0"
        rpy="0 0 0" />
      <geometry>
        <mesh
          filename="package://rh1621hand_y/meshes/fy1643_Link.STL" />
      </geometry>
    </collision>
  </link>
  <joint
    name="fy1643"
    type="revolute">
    <origin
      xyz="-0.03998 -0.0032593 0.002334"
      rpy="0 0 0" />
    <parent
      link="fy1642_Link" />
    <child
      link="fy1643_Link" />
    <axis
      xyz="0 0 -1" />
    <limit
      lower="0"
      upper="1.406"
      effort="0"
      velocity="0" />
  </joint>
  <link
    name="fy1644_Link">
    <inertial>
      <origin
        xyz="-0.00367976600360337 -0.00489152959002746 0.00846584217432496"
        rpy="0 0 0" />
      <mass
        value="0.00405498012712194" />
      <inertia
        ixx="1.94079478041612E-07"
        ixy="-9.40631754867392E-08"
        ixz="3.20649158280789E-12"
        iyy="2.96879075675208E-07"
        iyz="5.62155099485548E-12"
        izz="3.37103375720116E-07" />
    </inertial>
    <visual>
      <origin
        xyz="0 0 0"
        rpy="0 0 0" />
      <geometry>
        <mesh
          filename="package://rh1621hand_y/meshes/fy1644_Link.STL" />
      </geometry>
      <material
	      name="">
        <color
          rgba="0.898039215686275 0.917647058823529 0.929411764705882 1" />
      </material>
    </visual>
    <collision>
      <origin
        xyz="0 0 0"
        rpy="0 0 0" />
      <geometry>
        <mesh
          filename="package://rh1621hand_y/meshes/fy1644_Link.STL" />
      </geometry>
    </collision>
  </link>
  <joint
    name="fy1644"
    type="revolute">
    <origin
      xyz="-0.026577 0.0047606 -0.0002"
      rpy="0 0 0" />
    <parent
      link="fy1643_Link" />
    <child
      link="fy1644_Link" />
    <axis
      xyz="0 0 -1" />
    <limit
      lower="0"
      upper="1.169"
      effort="0"
      velocity="0" />
    <mimic joint="fy1643" multiplier="1.0" offset="0.0"/>
  </joint>
  <link
    name="fy1645_Link">
    <inertial>
      <origin
        xyz="6.88364520780305E-06 -0.00135005923625761 -0.0054662936718845"
        rpy="0 0 0" />
      <mass
        value="0.00215218868429395" />
      <inertia
        ixx="1.24856414999024E-07"
        ixy="6.62206163202925E-11"
        ixz="7.45657454822329E-11"
        iyy="1.58678581980123E-07"
        iyz="-2.48685099822782E-08"
        izz="1.01653807352178E-07" />
    </inertial>
    <visual>
      <origin
        xyz="0 0 0"
        rpy="0 0 0" />
      <geometry>
        <mesh
          filename="package://rh1621hand_y/meshes/fy1645_Link.STL" />
      </geometry>
      <material
	      name="">
        <color
          rgba="0.298039215686275 0.298039215686275 0.298039215686275 1" />
      </material>
    </visual>
    <collision>
      <origin
        xyz="0 0 0"
        rpy="0 0 0" />
      <geometry>
        <mesh
          filename="package://rh1621hand_y/meshes/fy1645_Link.STL" />
      </geometry>
    </collision>
  </link>
  <joint
    name="fy1645"
    type="revolute">
    <origin
      xyz="-0.018928 -0.0044 0.008466"
      rpy="-3.1416 1.5698 0" />
    <parent
      link="fy1644_Link" />
    <child
      link="fy1645_Link" />
    <axis
      xyz="0 0 -1" />
    <limit
      lower="0"
      upper="0"
      effort="0"
      velocity="0" />
  </joint>
  <link
    name="fy1651_Link">
    <inertial>
      <origin
        xyz="1.38777878078145E-17 6.93889390390723E-18 0.0144895176625968"
        rpy="0 0 0" />
      <mass
        value="0.00163674187446043" />
      <inertia
        ixx="4.9517908986217E-08"
        ixy="-2.30671620582074E-14"
        ixz="4.99852355695857E-25"
        iyy="8.5446998556508E-08"
        iyz="-1.33290123638887E-18"
        izz="4.31474049831044E-08" />
    </inertial>
    <visual>
      <origin
        xyz="0 0 0"
        rpy="0 0 0" />
      <geometry>
        <mesh
          filename="package://rh1621hand_y/meshes/fy1651_Link.STL" />
      </geometry>
      <material
	      name="">
        <color
          rgba="0.898039215686275 0.917647058823529 0.929411764705882 1" />
      </material>
    </visual>
    <collision>
      <origin
        xyz="0 0 0"
        rpy="0 0 0" />
      <geometry>
        <mesh
          filename="package://rh1621hand_y/meshes/fy1651_Link.STL" />
      </geometry>
    </collision>
  </link>
  <joint
    name="fy1651"
    type="revolute">
    <origin
      xyz="-0.018 -0.03525 0.114"
      rpy="1.5708 0 1.5708" />
    <parent
      link="base_link" />
    <child
      link="fy1651_Link" />
    <axis
      xyz="0 0 1" />
    <limit
      lower="-0.349"
      upper="0.349"
      effort="0"
      velocity="0" />
  </joint>
  <link
    name="fy1652_Link">
    <inertial>
      <origin
        xyz="-0.019864611102816 0.00014789361820898 0.0105074887188428"
        rpy="0 0 0" />
      <mass
        value="0.00868396741320419" />
      <inertia
        ixx="3.84741751932441E-07"
        ixy="-7.17649251243009E-09"
        ixz="-2.99382278098217E-08"
        iyy="1.05867098519524E-06"
        iyz="-1.10470761373444E-08"
        izz="1.26090390885764E-06" />
    </inertial>
    <visual>
      <origin
        xyz="0 0 0"
        rpy="0 0 0" />
      <geometry>
        <mesh
          filename="package://rh1621hand_y/meshes/fy1652_Link.STL" />
      </geometry>
      <material
	      name="">
        <color
          rgba="0.898039215686275 0.917647058823529 0.929411764705882 1" />
      </material>
    </visual>
    <collision>
      <origin
        xyz="0 0 0"
        rpy="0 0 0" />
      <geometry>
        <mesh
          filename="package://rh1621hand_y/meshes/fy1652_Link.STL" />
      </geometry>
    </collision>
  </link>
  <joint
    name="fy1652"
    type="revolute">
    <origin
      xyz="0.0105 0 0.0208"
      rpy="1.5708 0 -1.5708" />
    <parent
      link="fy1651_Link" />
    <child
      link="fy1652_Link" />
    <axis
      xyz="0 0 -1" />
    <limit
      lower="0"
      upper="1.557"
      effort="0"
      velocity="0" />
  </joint>
  <link
    name="fy1653_Link">
    <inertial>
      <origin
        xyz="-0.0128029857467799 0.00108469576678104 0.00823130817829634"
        rpy="0 0 0" />
      <mass
        value="0.00454257121651392" />
      <inertia
        ixx="1.46881448958238E-07"
        ixy="3.58997015450153E-08"
        ixz="2.18137845869091E-09"
        iyy="3.73853639577905E-07"
        iyz="-6.65086421558295E-10"
        izz="4.59535882780797E-07" />
    </inertial>
    <visual>
      <origin
        xyz="0 0 0"
        rpy="0 0 0" />
      <geometry>
        <mesh
          filename="package://rh1621hand_y/meshes/fy1653_Link.STL" />
      </geometry>
      <material
	      name="">
        <color
          rgba="0.898039215686275 0.917647058823529 0.929411764705882 1" />
      </material>
    </visual>
    <collision>
      <origin
        xyz="0 0 0"
        rpy="0 0 0" />
      <geometry>
        <mesh
          filename="package://rh1621hand_y/meshes/fy1653_Link.STL" />
      </geometry>
    </collision>
  </link>
  <joint
    name="fy1653"
    type="revolute">
    <origin
      xyz="-0.03498 -0.0032273 0.002234"
      rpy="0 0 0" />
    <parent
      link="fy1652_Link" />
    <child
      link="fy1653_Link" />
    <axis
      xyz="0 0 -1" />
    <limit
      lower="0"
      upper="1.447"
      effort="0"
      velocity="0" />
  </joint>
  <link
    name="fy1654_Link">
    <inertial>
      <origin
        xyz="-0.00362332207658896 -0.00493349047469921 0.00846584197554688"
        rpy="0 0 0" />
      <mass
        value="0.00405498123801861" />
      <inertia
        ixx="1.96254645076027E-07"
        ixy="-9.52195762862316E-08"
        ixz="3.18762889599832E-12"
        iyy="2.94704272343394E-07"
        iyz="5.69022062942663E-12"
        izz="3.37103832106316E-07" />
    </inertial>
    <visual>
      <origin
        xyz="0 0 0"
        rpy="0 0 0" />
      <geometry>
        <mesh
          filename="package://rh1621hand_y/meshes/fy1654_Link.STL" />
      </geometry>
      <material
	      name="">
        <color
          rgba="0.898039215686275 0.917647058823529 0.929411764705882 1" />
      </material>
    </visual>
    <collision>
      <origin
        xyz="0 0 0"
        rpy="0 0 0" />
      <geometry>
        <mesh
          filename="package://rh1621hand_y/meshes/fy1654_Link.STL" />
      </geometry>
    </collision>
  </link>
  <joint
    name="fy1654"
    type="revolute">
    <origin
      xyz="-0.026605 0.0046031 -0.0002"
      rpy="0 0 0" />
    <parent
      link="fy1653_Link" />
    <child
      link="fy1654_Link" />
    <axis
      xyz="0 0 -1" />
    <limit
      lower="0"
      upper="1.185"
      effort="0"
      velocity="0" />
    <mimic joint="fy1653" multiplier="1.0" offset="0.0"/>
  </joint>
  <link
    name="fy1655_Link">
    <inertial>
      <origin
        xyz="1.479283593675E-06 -0.00141278078825598 -0.0054504137031022"
        rpy="0 0 0" />
      <mass
        value="0.00215219249919118" />
      <inertia
        ixx="1.24856694097198E-07"
        ixy="4.21947884637066E-11"
        ixz="5.10844728991536E-11"
        iyy="1.58099694850744E-07"
        iyz="-2.55172206098674E-08"
        izz="1.02232782074789E-07" />
    </inertial>
    <visual>
      <origin
        xyz="0 0 0"
        rpy="0 0 0" />
      <geometry>
        <mesh
          filename="package://rh1621hand_y/meshes/fy1655_Link.STL" />
      </geometry>
      <material
	      name="">
        <color
          rgba="0.298039215686275 0.298039215686275 0.298039215686275 1" />
      </material>
    </visual>
    <collision>
      <origin
        xyz="0 0 0"
        rpy="0 0 0" />
      <geometry>
        <mesh
          filename="package://rh1621hand_y/meshes/fy1655_Link.STL" />
      </geometry>
    </collision>
  </link>
  <joint
    name="fy1655"
    type="revolute">
    <origin
      xyz="-0.018876 -0.0046172 0.008466"
      rpy="-3.1416 1.5708 0" />
    <parent
      link="fy1654_Link" />
    <child
      link="fy1655_Link" />
    <axis
      xyz="0 0 -1" />
    <limit
      lower="0"
      upper="0"
      effort="0"
      velocity="0" />
  </joint>

<transmission name="trans_fy1611">
    <type>transmission_interface/SimpleTransmission</type>
    <joint name="fy1611">
      <hardwareInterface>EffortJointInterface</hardwareInterface>
    </joint>
    <actuator name="actuator_fy1611">
      <hardwareInterface>EffortJointInterface</hardwareInterface>
      <mechanicalReduction>1</mechanicalReduction>
    </actuator>
  </transmission>
  <transmission name="trans_fy1612">
    <type>transmission_interface/SimpleTransmission</type>
    <joint name="fy1612">
      <hardwareInterface>EffortJointInterface</hardwareInterface>
    </joint>
    <actuator name="actuator_fy1612">
      <hardwareInterface>EffortJointInterface</hardwareInterface>
      <mechanicalReduction>1</mechanicalReduction>
    </actuator>
  </transmission>
  <transmission name="trans_fy1613">
    <type>transmission_interface/SimpleTransmission</type>
    <joint name="fy1613">
      <hardwareInterface>EffortJointInterface</hardwareInterface>
    </joint>
    <actuator name="actuator_fy1613">
      <hardwareInterface>EffortJointInterface</hardwareInterface>
      <mechanicalReduction>1</mechanicalReduction>
    </actuator>
  </transmission>
  <transmission name="trans_fy1614">
    <type>transmission_interface/SimpleTransmission</type>
    <joint name="fy1614">
      <hardwareInterface>EffortJointInterface</hardwareInterface>
    </joint>
    <actuator name="actuator_fy1614">
      <hardwareInterface>EffortJointInterface</hardwareInterface>
      <mechanicalReduction>1</mechanicalReduction>
    </actuator>
  </transmission>
  <transmission name="trans_fy1615">
    <type>transmission_interface/SimpleTransmission</type>
    <joint name="fy1615">
      <hardwareInterface>EffortJointInterface</hardwareInterface>
    </joint>
    <actuator name="actuator_fy1615">
      <hardwareInterface>EffortJointInterface</hardwareInterface>
      <mechanicalReduction>1</mechanicalReduction>
    </actuator>
  </transmission>
  <transmission name="trans_fy1616">
    <type>transmission_interface/SimpleTransmission</type>
    <joint name="fy1616">
      <hardwareInterface>EffortJointInterface</hardwareInterface>
    </joint>
    <actuator name="actuator_fy1616">
      <hardwareInterface>EffortJointInterface</hardwareInterface>
      <mechanicalReduction>1</mechanicalReduction>
    </actuator>
  </transmission>
  <transmission name="trans_fy1621">
    <type>transmission_interface/SimpleTransmission</type>
    <joint name="fy1621">
      <hardwareInterface>EffortJointInterface</hardwareInterface>
    </joint>
    <actuator name="actuator_fy1621">
      <hardwareInterface>EffortJointInterface</hardwareInterface>
      <mechanicalReduction>1</mechanicalReduction>
    </actuator>
  </transmission>
  <transmission name="trans_fy1622">
    <type>transmission_interface/SimpleTransmission</type>
    <joint name="fy1622">
      <hardwareInterface>EffortJointInterface</hardwareInterface>
    </joint>
    <actuator name="actuator_fy1622">
      <hardwareInterface>EffortJointInterface</hardwareInterface>
      <mechanicalReduction>1</mechanicalReduction>
    </actuator>
  </transmission>
  <transmission name="trans_fy1623">
    <type>transmission_interface/SimpleTransmission</type>
    <joint name="fy1623">
      <hardwareInterface>EffortJointInterface</hardwareInterface>
    </joint>
    <actuator name="actuator_fy1623">
      <hardwareInterface>EffortJointInterface</hardwareInterface>
      <mechanicalReduction>1</mechanicalReduction>
    </actuator>
  </transmission>
  <transmission name="trans_fy1624">
    <type>transmission_interface/SimpleTransmission</type>
    <joint name="fy1624">
      <hardwareInterface>EffortJointInterface</hardwareInterface>
    </joint>
    <actuator name="actuator_fy1624">
      <hardwareInterface>EffortJointInterface</hardwareInterface>
      <mechanicalReduction>1</mechanicalReduction>
    </actuator>
  </transmission>
  <transmission name="trans_fy1625">
    <type>transmission_interface/SimpleTransmission</type>
    <joint name="fy1625">
      <hardwareInterface>EffortJointInterface</hardwareInterface>
    </joint>
    <actuator name="actuator_fy1625">
      <hardwareInterface>EffortJointInterface</hardwareInterface>
      <mechanicalReduction>1</mechanicalReduction>
    </actuator>
  </transmission>
  <transmission name="trans_fy1631">
    <type>transmission_interface/SimpleTransmission</type>
    <joint name="fy1631">
      <hardwareInterface>EffortJointInterface</hardwareInterface>
    </joint>
    <actuator name="actuator_fy1631">
      <hardwareInterface>EffortJointInterface</hardwareInterface>
      <mechanicalReduction>1</mechanicalReduction>
    </actuator>
  </transmission>
  <transmission name="trans_fy1632">
    <type>transmission_interface/SimpleTransmission</type>
    <joint name="fy1632">
      <hardwareInterface>EffortJointInterface</hardwareInterface>
    </joint>
    <actuator name="actuator_fy1632">
      <hardwareInterface>EffortJointInterface</hardwareInterface>
      <mechanicalReduction>1</mechanicalReduction>
    </actuator>
  </transmission>
  <transmission name="trans_fy1633">
    <type>transmission_interface/SimpleTransmission</type>
    <joint name="fy1633">
      <hardwareInterface>EffortJointInterface</hardwareInterface>
    </joint>
    <actuator name="actuator_fy1633">
      <hardwareInterface>EffortJointInterface</hardwareInterface>
      <mechanicalReduction>1</mechanicalReduction>
    </actuator>
  </transmission>
  <transmission name="trans_fy1634">
    <type>transmission_interface/SimpleTransmission</type>
    <joint name="fy1634">
      <hardwareInterface>EffortJointInterface</hardwareInterface>
    </joint>
    <actuator name="actuator_fy1634">
      <hardwareInterface>EffortJointInterface</hardwareInterface>
      <mechanicalReduction>1</mechanicalReduction>
    </actuator>
  </transmission>
  <transmission name="trans_fy1635">
    <type>transmission_interface/SimpleTransmission</type>
    <joint name="fy1635">
      <hardwareInterface>EffortJointInterface</hardwareInterface>
    </joint>
    <actuator name="actuator_fy1635">
      <hardwareInterface>EffortJointInterface</hardwareInterface>
      <mechanicalReduction>1</mechanicalReduction>
    </actuator>
  </transmission>
  <transmission name="trans_fy1641">
    <type>transmission_interface/SimpleTransmission</type>
    <joint name="fy1641">
      <hardwareInterface>EffortJointInterface</hardwareInterface>
    </joint>
    <actuator name="actuator_fy1641">
      <hardwareInterface>EffortJointInterface</hardwareInterface>
      <mechanicalReduction>1</mechanicalReduction>
    </actuator>
  </transmission>
  <transmission name="trans_fy1642">
    <type>transmission_interface/SimpleTransmission</type>
    <joint name="fy1642">
      <hardwareInterface>EffortJointInterface</hardwareInterface>
    </joint>
    <actuator name="actuator_fy1642">
      <hardwareInterface>EffortJointInterface</hardwareInterface>
      <mechanicalReduction>1</mechanicalReduction>
    </actuator>
  </transmission>
  <transmission name="trans_fy1643">
    <type>transmission_interface/SimpleTransmission</type>
    <joint name="fy1643">
      <hardwareInterface>EffortJointInterface</hardwareInterface>
    </joint>
    <actuator name="actuator_fy1643">
      <hardwareInterface>EffortJointInterface</hardwareInterface>
      <mechanicalReduction>1</mechanicalReduction>
    </actuator>
  </transmission>
  <transmission name="trans_fy1644">
    <type>transmission_interface/SimpleTransmission</type>
    <joint name="fy1644">
      <hardwareInterface>EffortJointInterface</hardwareInterface>
    </joint>
    <actuator name="actuator_fy1644">
      <hardwareInterface>EffortJointInterface</hardwareInterface>
      <mechanicalReduction>1</mechanicalReduction>
    </actuator>
  </transmission>
  <transmission name="trans_fy1645">
    <type>transmission_interface/SimpleTransmission</type>
    <joint name="fy1645">
      <hardwareInterface>EffortJointInterface</hardwareInterface>
    </joint>
    <actuator name="actuator_fy1645">
      <hardwareInterface>EffortJointInterface</hardwareInterface>
      <mechanicalReduction>1</mechanicalReduction>
    </actuator>
  </transmission>
  <transmission name="trans_fy1651">
    <type>transmission_interface/SimpleTransmission</type>
    <joint name="fy1651">
      <hardwareInterface>EffortJointInterface</hardwareInterface>
    </joint>
    <actuator name="actuator_fy1651">
      <hardwareInterface>EffortJointInterface</hardwareInterface>
      <mechanicalReduction>1</mechanicalReduction>
    </actuator>
  </transmission>
  <transmission name="trans_fy1652">
    <type>transmission_interface/SimpleTransmission</type>
    <joint name="fy1652">
      <hardwareInterface>EffortJointInterface</hardwareInterface>
    </joint>
    <actuator name="actuator_fy1652">
      <hardwareInterface>EffortJointInterface</hardwareInterface>
      <mechanicalReduction>1</mechanicalReduction>
    </actuator>
  </transmission>
  <transmission name="trans_fy1653">
    <type>transmission_interface/SimpleTransmission</type>
    <joint name="fy1653">
      <hardwareInterface>EffortJointInterface</hardwareInterface>
    </joint>
    <actuator name="actuator_fy1653">
      <hardwareInterface>EffortJointInterface</hardwareInterface>
      <mechanicalReduction>1</mechanicalReduction>
    </actuator>
  </transmission>
  <transmission name="trans_fy1654">
    <type>transmission_interface/SimpleTransmission</type>
    <joint name="fy1654">
      <hardwareInterface>EffortJointInterface</hardwareInterface>
    </joint>
    <actuator name="actuator_fy1654">
      <hardwareInterface>EffortJointInterface</hardwareInterface>
      <mechanicalReduction>1</mechanicalReduction>
    </actuator>
  </transmission>
  <transmission name="trans_fy1655">
    <type>transmission_interface/SimpleTransmission</type>
    <joint name="fy1655">
      <hardwareInterface>EffortJointInterface</hardwareInterface>
    </joint>
    <actuator name="actuator_fy1655">
      <hardwareInterface>EffortJointInterface</hardwareInterface>
      <mechanicalReduction>1</mechanicalReduction>
    </actuator>
  </transmission>





</robot>
